## 예외 1 - 문법

#### 성공과 실패

- 예외는 실패하지 않는 법에 대한 수업이다
- 덜 실패하는 법은 실패의 크기를 줄여주는 효과 뿐 아니라 실패에 대한 두려움을 억제해서 성공하는 법을 보다 적극적으로 시도할 수 있게 촉진한다는 점에서 중요하다

#### 예외란?

- 오류라는 것은 예외의 일종
- 예외(Exception):  프로그램을 만든 프로그래머가 상정한 정상적인 처리에서 벗어나는 경우에 이를 처리하기 위한 방법이다

```java
package org.opentutorials.javatutorials.exception;
class Calculator{
    int left, right;
    public void setOprands(int left, int right){
        this.left = left;
        this.right = right;
    }
    public void divide(){
        System.out.print("계산결과는 ");
        System.out.print(this.left/this.right);
        System.out.print(" 입니다.");
    }
} 
public class CalculatorDemo {
    public static void main(String[] args) {
        Calculator c1 = new Calculator();
        c1.setOprands(10, 0);
        c1.divide();
    }
}
```

- 오류 발생
- 10을 0으로 나눌 수 없다

*변경 코드*
![](https://s3.ap-northeast-2.amazonaws.com/opentutorials-user-file/module/516/2053.png)

*실행결과*
```java
계산결과는 오류가 발생했습니다 : / by zero
계산결과는 2 입니다.
```

#### try...catch

- try...catch는 예외에서 핵심적인 역할을 담당하는 문법적인 요소다

#### try 

![](https://s3.ap-northeast-2.amazonaws.com/opentutorials-user-file/module/516/2050.png)

#### catch

![](https://s3.ap-northeast-2.amazonaws.com/opentutorials-user-file/module/516/2051.png)

- 오류가 발생하면서 try 내의 실행이 중단되고 catch 구문 안의 내용이 실행되었음을 의미한다

#### 예외 클래스와 인스턴스

![](https://s3.ap-northeast-2.amazonaws.com/opentutorials-user-file/module/516/2052.png)


#### 뒷수습의 방법

*변경 코드*<br>
![](https://s3.ap-northeast-2.amazonaws.com/opentutorials-user-file/module/516/2054.png)

*실행결과*

```java
계산결과는 
 
e.getMessage()
/ by zero
 
 
e.toString()
java.lang.ArithmeticException: / by zero
 
 
e.printStackTrace()
java.lang.ArithmeticException: / by zero
    at org.opentutorials.javatutorials.exception.Calculator.divide(CalculatorDemo.java:11)
    at org.opentutorials.javatutorials.exception.CalculatorDemo.main(CalculatorDemo.java:25)
```

#### e.getMessage();

- 오류에 대한 기본적인 내용을 출력해준다

#### e.toString()

- e라고 하는 인스턴스의 대한 자세한 정보를 출력해준다

#### e.printStackTrace()

- 이 메소드를 호출하면 메소드가 내부적으로 예외 결과를 화면에 출력한다
- printStackTrace는 가장 자세한 예외 정보를 제공한다

- 예외가 발생했을 때 try...catch가 실행되고 그 메소드의 동작이 중단되는 것이 아니고 catch 안에 있는 구문 다 실행되면 catch 바깥에 있는 로직이 실행된다

#### 다양한 예외들

```java
package org.opentutorials.javatutorials.exception;
 
class A{
    private int[] arr = new int[3];
    A(){
        arr[0]=0;
        arr[1]=10;
        arr[2]=20;
    }
    public void z(int first, int second){
        System.out.println(arr[first] / arr[second]);
    }
}
 
public class ExceptionDemo1 {
    public static void main(String[] args) {
        A a = new A();
        a.z(10, 1);
    }
}
```

- 존재하지 않는 값을 가져오려고 시도하고 있기 때문에 오류 발생

*변경 코드*<br>
![](https://s3.ap-northeast-2.amazonaws.com/opentutorials-user-file/module/516/2056.png)

-  else if처럼 여러 개의 catch를 하나의 try 구문에서 사용할 수 있다
- 문제가 무엇이냐에 따라서 더 적합한 해결방법을 선택 할 수 있다

*변경 코드*<br>
![](https://s3.ap-northeast-2.amazonaws.com/opentutorials-user-file/module/516/2057.png)

- 컴파일 조차 되지 않는다
-  Exception이 ArrayIndexOutOfBoundsException, ArithemeticException 보다 포괄적인 예외를 의미하기 때문에 Exception 이후에 등장하는 catch 문은 실행될 수 없는 구문이기 때문이다

#### finally

![](https://s3.ap-northeast-2.amazonaws.com/opentutorials-user-file/module/516/2058.png

- try, catch 구문과 무관하게 실행된다

*변경 코드*<br>
![](https://s3.ap-northeast-2.amazonaws.com/opentutorials-user-file/module/516/2060.png)

*실행 결과*
```java
ArrayIndexOutOfBoundsException
finally
ArithmeticException
finally
2
finally
```

- 예외와 상관없이 언제나 finally가 실행된다

- 예외: 정상적인 처리에서 벗어나는 어떠한 문제가 발생했을데 그 문제를 해결하기 위한 방법을 자바에서 제공하는 체계

## 예외 2 - 예외 던지기

#### 예외의 강제

```java
package org.opentutorials.javatutorials.exception;
import java.io.*;
public class CheckedExceptionDemo {
    public static void main(String[] args) {
        BufferedReader bReader = new BufferedReader(new FileReader("out.txt"));
        String input = bReader.readLine();
        System.out.println(input); 
    }
}
```
- 파일의 내용을 출력해주는 코드

![](https://s3.ap-northeast-2.amazonaws.com/opentutorials-user-file/module/516/2066.png)
- 필자의 화면을 공유하면 아래와 같은 위치에 이 파일이 있어야 한다

*실행 결과*
```java
Exception in thread "main" java.lang.Error: Unresolved compilation problems: 
    Unhandled exception type FileNotFoundException
    Unhandled exception type IOException
 
    at org.opentutorials.javatutorials.exception.CheckedExceptionDemo.main(CheckedExceptionDemo.java:5)
```
- 오류 발생

![](https://s3.ap-northeast-2.amazonaws.com/opentutorials-user-file/module/516/2067.png)

- Throws는 한국어로는 '던지다'로 번역된다
- 생성자 FileReader의 인자 fileName의 값에 해당하는 파일이 디렉토리이거나 어떤 이유로 사용할 수 없다면 FileNotFoundException을 발생시킨다는 의미다

*변경 코드*
```java
package org.opentutorials.javatutorials.exception;
import java.io.*;
public class CheckedExceptionDemo {
    public static void main(String[] args) {
        BufferedReader bReader = null;
        String input = null;
        try {
            bReader = new BufferedReader(new FileReader("out.txt"));
        } catch (FileNotFoundException e) {
            e.printStackTrace();
        }
        try{
            input = bReader.readLine();
        } catch (IOException e){
            e.printStackTrace();
        }       
        System.out.println(input); 
    }
}
```

#### throw와 throws

```java
package org.opentutorials.javatutorials.exception;
 
class B{
    void run(){
    }
}
class C{
    void run(){
        B b = new B();
        b.run();
    }
}
public class ThrowExceptionDemo {
    public static void main(String[] args) {
         C c = new C();
         c.run();
    }   
}
```

- ThrowExceptionDem의 메소드 main)은 C.run의 사용자이다
-  C.run은 B.run의 사용자이다
- B -> C-> Throw -> 일반 사용자

*변경 코드*<br>
![](https://s3.ap-northeast-2.amazonaws.com/opentutorials-user-file/module/516/2075.png)
- B.run이 FileReader의 생성자와 BufferedReader.readLine가 던진 예외를 try...catch로 처리한다
- B.run이 예외 처리를 직접 하지 않고 다음 사용자 C.run에게 넘길 수 있다

*변경 코드*<br>
![](https://s3.ap-northeast-2.amazonaws.com/opentutorials-user-file/module/516/2076.png)
- 오류 발생
- run 옆에 throws IOException, FileNotFoundException이 추가
-  B.run 내부에서 예외가 발생하면 이에 대한 처리를 B.run의 사용자에게 위임하는 것이다
- 위의 코드에서 B.run의 사용자는 C.run이다. 따라서 C.run은 아래와 같이 수정돼야 한다

*변경 코드*<br>
![](https://s3.ap-northeast-2.amazonaws.com/opentutorials-user-file/module/516/2077.png)



*책임을 main에게 넘김*

![](https://s3.ap-northeast-2.amazonaws.com/opentutorials-user-file/module/516/2079.png)

- try...catch: 자기가 처리
- throw: 다름 사용자에게 넘김
- 예외는 API를 사용하면서 발생할 수 있는 잠재적 위협에 대한 API 개발자의 강력한 암시다

## 예외 3 - 만들기

#### 소비자에서 생선자로

```java
package org.opentutorials.javatutorials.exception;
class Calculator{
    int left, right;
    public void setOprands(int left, int right){
        this.left = left;
        this.right = right;
    }
    public void divide(){
        try {
            System.out.print("계산결과는 ");
            System.out.print(this.left/this.right);
            System.out.print(" 입니다.");
        } catch(Exception e){
            System.out.println("\n\ne.getMessage()\n"+e.getMessage());
            System.out.println("\n\ne.toString()\n"+e.toString());
            System.out.println("\n\ne.printStackTrace()");
            e.printStackTrace();
        }
    }
} 
public class CalculatorDemo {
    public static void main(String[] args) {
        Calculator c1 = new Calculator();
        c1.setOprands(10, 0);
        c1.divide();
    }
}
```
- 오류 발생
- 0으로 나눔

- 해결 방법
    - setOprands의 두번째 인자로 0이 들어오면 예외를 발생시킨다
    ![](https://s3.ap-northeast-2.amazonaws.com/opentutorials-user-file/module/516/2080.png)
    - 메소드 divide를 실행할 때 right의 값이 0이라면 예외를 발생시킨다<br>
    *divide 내에서 예외를 처리*
    ![](https://s3.ap-northeast-2.amazonaws.com/opentutorials-user-file/module/516/2081.png)


*주요 Exception들의 리스트*
|예외|사용해야 할 상황|
|:---|:---|
|IllegalArgumentException|매개변수가 의도하지 않은 상황을 유발시킬 때|
|IllegalStateException|메소드를 호출하기 위한 상태가 아닐 때|
|NullPointerException|매개 변수 값이 null 일 때|
|IndexOutOfBoundsException|인덱스 매개 변수 값이 범위를 벗어날 때|
|ArithmeticException|산술적인 연산에 오류가 있을 때|

#### 예외의 여러가지 상황들

```java
package org.opentutorials.javatutorials.exception;
class E{
    void throwArithmeticException(){
        throw new ArithmeticException();
    }
}
```
- 문제 없이 컴파일

```java
package org.opentutorials.javatutorials.exception;
import java.io.IOException;
class E{
    void throwArithmeticException(){
        throw new ArithmeticException();
    }
    void throwIOException(){
        throw new IOException();
    }
}
```
- 에러 발생
- IOException은 try...catch하거나 throw 해야 한다

*변경 코드*<br>
![](https://s3.ap-northeast-2.amazonaws.com/opentutorials-user-file/module/516/2087.png)

#### 예외의 선조 - Throwable

![](https://s3.ap-northeast-2.amazonaws.com/opentutorials-user-file/module/516/2061.png)

-  ArithmeticException의 부모 클래스 중에 java.lang.Exception 클래스가 있다는 사실을 알 수 있다
-  Exception 클래스가 더 많은 예외 상황을 포괄하는 것이고 ArithmeticException 클래스는 더 구체적인 상황을 특정하는 것이다

*Throwable 클래스*<br>
![](https://s3.ap-northeast-2.amazonaws.com/opentutorials-user-file/module/516/2063.png)

- Throwable =  '던질 수 있는'

#### 예외의 종류

- Throwable
- Error
- Exception
- Runtime Exception

![](https://s3.ap-northeast-2.amazonaws.com/opentutorials-user-file/module/516/2099.png)

#### Throwable
- 모든 예외 클래스의 부모 

#### Error
- Throwable을 직접 상속
- 애플리케이션의 문제가 아니라 그 애플리케이션이 동작하는 가상머신에 문제가 생겼을 때

#### IOException
- 부모중에 RuntimeException이 없음

#### ArithmeticException
- 부모중에 RuntimeException이 있음

#### Exception
- checked 예외 - RuntimeException을 제외한 Exception의 하위 클래스

- unchekced 예외 - RuntimeException의 하위 클래스
    
- checked 예외는 반드시 예외처리를 해야 하는 되는 것이고, unchekced는 해도 되고 안 해도 되는 예외다

![](https://s3.ap-northeast-2.amazonaws.com/opentutorials-user-file/module/516/2093.png)
-  IOException은 checked이고 ArithmeticException은 unchekced이다. (Error도 unchecked이다)

#### 나만의 예외 만들기

-  자신의 예외를 checked로 할 것인가? unchecked로 할 것인가를 정해야 한다
    - API 쪽에서 예외를 던졌을 때 API 사용자 쪽에서 예외 상황을 복구 할 수 있다면 checked 예외를 사용
    - checked 예외는 사용자에게 문제를 해결할 기회를 주는 것이면서 예외처리를 강제하는 것

*직접 만든 Exception으로 교체*
```java
package org.opentutorials.javatutorials.exception;
class DivideException extends RuntimeException {
    DivideException(){
        super();
    }
    DivideException(String message){
        super(message);
    }
}
class Calculator{
    int left, right;
    public void setOprands(int left, int right){        
        this.left = left;
        this.right = right;
    }
    public void divide(){
        if(this.right == 0){
            throw new DivideException("0으로 나누는 것은 허용되지 않습니다.");
        }
        System.out.print(this.left/this.right);
    }
}
public class CalculatorDemo {
    public static void main(String[] args) {
        Calculator c1 = new Calculator();
        c1.setOprands(10, 0);
        c1.divide();
    }
}
```
- 오류 발생
- checked로 예외처리를 강제

*변경 코드1*<br>
![](https://s3.ap-northeast-2.amazonaws.com/opentutorials-user-file/module/516/2095.png)

*변경 코드2*<br>
![](https://s3.ap-northeast-2.amazonaws.com/opentutorials-user-file/module/516/2096.png)
